# 异常编写细节

## try/except/else语句

try是一种包含多个块的复合语句。它以try作为首行，后面紧跟着缩进的语句代码；然后是一个或多个except分局来识别要捕捉的异常以及相应的处理代码块；最后一个可选的else分句及相应代码块。

```
try:
    statments
except name1:
    statments
except (name2,name3):
    statments
except name4 as var:
    statments
except:
    statments
else:
    statments
```

### try语句的工作方式

当try语句启动时，Python会标识当前的程序上下文，如果之后有异常发生时，才能返回这里。try首行下的语句会事先执行。接下来会发生什么事，取决于try代码块语句执行时是否引发异常，以及这些异常的类型是否能和try监听的类型相匹配：

- 如果try代码块语句执行时发生了一个异常，Python就跳回try，把引发的异常对象赋值给as分句后面的变量名，然后执行第一个符合引发异常的except分句下面的语句。当except代码块执行后，控制权就会移交到整个try语句的后面继续执行。
- 如果异常发生在try代码块内，但却不能跟当前try语句的任何except分句描述的名字相匹配，那么异常就会向上传递到程序之前最近一次进入的能够匹配的try中；如果都找不到这样能匹配的try语句，而且搜索已经到达了进程的顶层，Python就会终止这个程序并打印一条默认的出错信息。
- 如果try首行底下执行的语句没有发生异常，Python就会执行else行下的语句，之后控制权会从整个语句的后面继续。

except分句会捕捉try代码块执行时所发生的任何能匹配的异常，而else分句当且仅当在try代码块的执行不发生异常时才会运行。异常通过类继承关系与except分句中的有一场名称进行匹配，同时空except分句能够匹配所有的异常。

except分句是专门的异常处理程序：它们值捕捉在对应try代码块中的语句所发生的异常。因为try代码块语句可以调用写在程序其他地方的函数，异常的来源可能会在try语句自身之外。

try语句能够在运行时嵌套。

### try语句分句

except分句会捕捉异常；finally分句最后一定会执行；如果没有遇上异常，else分句就会执行。

except分句数量可以随意选择，但是你只能存在一条except分句的时候才能编写else分句，而且最多只能编写一个else分句和一个finally分句。

#### 捕获任何和所有异常

```
try:
	action()
except NameError:
	...
except IndexError:
	...
except KeyError:
	...
except (AttributeError,TypeError,SyntaxError):
	...
except:
    ...
else:
	...
```

空的except分句具有类似通配符的功能。因为它能匹配任意的异常，所以可以让处理程序按照你的需求变得通用化或具体化。在某些场合下，比起列出的try中所有可能异常来说，这种形式反而更方便一些。

### try else 分句

#### 示例：默认行为

```python
def gobad(x,y):
    return x/y

def gosouth(x):
    print(gobad(x,0))
    
gosouth(1)

Traceback (most recent call last):
  File "bad.py", line 7, in <module>
    gosouth(1)
  File "bad.py", line 5, in gosouth
    print(gobad(x,0))
  File "bad.py", line 2, in gobad
    return x/y
ZeroDivisionError: division by zero
```

#### 示例：捕获内置异常

```python
def kaboom(x,y):
    print(x+y)
    
try:
    kaboom([0,1,2],'spam')
except TypeError:
    print('Hello world')
print('resuming here')

Hello world
resuming here
```

## try/finally语句

```
try:
	statements
finally:
	statements
```

- 如果try代码块运行时没有异常发生，Python便会跳至执行finally代码块，然后在整个try语句的后面继续执行下去。
- 如果try代码块运行时有异常发生，Python依然会回来运行finally代码块，但是接着会把异常向上传递到更外层的try语句或顶层默认处理程序；程序不会在finally分句的try语句的下面继续执行。finally不会终止异常。

#### 示例：利用try/finally编写终止行为

```python
class MyError(Exception): pass

def stuff(file):
    raise MyError()
    
file = open('data','w')
try:
    stuff(file)
finally:
    file.close()
print('not reached')
```

