# 错误和异常

## 句法错误

句法错误又称解析错误：

```
while True print('Hello world')
  File "<stdin>", line 1
    while True print('Hello world')
                   ^
SyntaxError: invalid syntax
```

## 异常

即使语句或表达式使用了正确的语法，执行时仍可能触发错误。执行时检测到的错误称为 异常。

```
>>> 10 * (1/0)
Traceback (most recent call last):
  File "<stdin>", line 1, in <module>
ZeroDivisionError: division by zero
>>> 4 + spam*3
Traceback (most recent call last):
  File "<stdin>", line 1, in <module>
NameError: name 'spam' is not defined
>>> '2' + 2
Traceback (most recent call last):
  File "<stdin>", line 1, in <module>
TypeError: can only concatenate str (not "int") to str
```

## 异常的处理

```python
while True:
    try:
        x = int(input("please enter a number: "))
        break
    except ValueError:
        print("Oops! That was no valid number. Try agian...")
```

try语句的工作原理如下：

- 首先，执行 try子句
- 如果没有触发异常，则跳过 except 子句，try语句执行完毕。
- 如果在执行try子句时发生了异常，则跳过该子句中剩下的部分。如果异常的类型与except关键字后指定的异常相匹配，则会执行except子句，然后跳到try/except代码块之后继续执行。
- 如果发生的异常与except子句中指定的异常不匹配，则它会被传递到外部的try语句中；如果没有找到处理程序，则它是一个未处理异常且执行将终止并输出异常信息。

try语句可以有多个except子句来为不同的异常制定处理程序。但最多只有一个处理程序会被执行。处理程序值处理对应的try子句中发生的异常，而不处理同一try语句内其他处理程序中的异常。except子句可以用圆括号的元祖来指定多个异常：

```
... except (RuntimeError,TypeError,NameError):
...     pass
```

如果发生的异常与except子句中的类是同一个类或是它的基类时，则该类与该异常相兼容。

```python
class B(Exception):
    pass
class C(B):
    pass
class D(C):
    pass
for cls in [B,C,D]:
    try:
        raise cls()
    except D:
        print("D")
    except C:
        print("C")
    except B:
        print("B")
```

如果颠倒except子句的顺序（把except B 放在最前），则会输出B,B,B --- 即触发了第一个匹配的except子句。

所有异常都继承自BaseException，因此它可被用作通配符。但是它很容易掩盖真正的编程错误。

```python
import sys

try:
    f = open('myfile.txt')
    s = f.readline()
    i = int(s.strip())
except OSError as err:
    print("OS error:{0}".format(err))
except ValueError:
    print("Could not convert data to an integer")
except BaseException as err:
	print(f"Unexpected {err=},{type(err)=}")
	raise
```

try...except 语句具有可选的else子句。该子句如果存在，它必须放在所有except子句之后。它适用于try子句没有引发异常但有必须要执行的代码：

```python
for arg in sys.argv[1:]:
    try:
        f = open(arg, 'r')
    except OSError:
        print('cannot open', arg)
    else:
        print(arg, 'has', len(f.readlines()), 'lines')
        f.close()
```

使用else子句比向try子句添加额外的代码要好，可以避免意外捕获非try...except语句保护的代码触发的异常。

```python
try:
    raise Exception('spam', 'eggs')
except Exception as inst:
    print(type(inst))    # the exception instance
    print(inst.args)     # arguments stored in .args
    print(inst)          # __str__ allows args to be printed directly,
                         # but may be overridden in exception subclasses
    x, y = inst.args     # unpack args
    print('x =', x)
    print('y =', y)
```

如果异常有参数，则它们将作为未处理异常的消息的最后一部分（'详细信息'）打印。

异常处理程序不仅会处理在try子句中发生的异常，还会处理在try子句中调用的函数：

```python
def this_fails():
    x = 1/0

try:
    this_fails()
except ZeroDivisionError as err:
    print('Handling run-time error:', err)
```

## 触发异常

raise语句支持强制触发指定的异常：

```
>>> raise NameError('HiThere')
Traceback (most recent call last):
  File "<stdin>", line 1, in <module>
NameError: HiThere
```

raise唯一的参数就是要触发的异常。这个参数必须时异常实例或异常类。如果传递的时异常类，将通过调用没有参数的构造函数来隐式实例化：

```python
raise ValueError
```

如果只想判断是否触发了异常，但并不打算处理该异常，则可以使用更简单的raise语句重新触发异常：

```
>>> try:
...     raise NameError('HiThere')
... except NameError:
...     print('An exception flew by!')
...     raise
...
An exception flew by!
Traceback (most recent call last):
  File "<stdin>", line 2, in <module>
NameError: HiThere
```

## 异常链

raise 语句支持可选的from子句，该子句用于启用链式异常：

```
raise RuntimeError from exc
```

转换异常时：

```
>>> def func():
...     raise ConnectionError
...
>>> try:
...     func()
... except ConnectionError as exc:
...     raise RuntimeError('Failed to open database') from exc
...
Traceback (most recent call  last):
  File "<stdin>", line 2, in <module>
  File "<stdin>", line 2, in func
ConnectionError

The above exception was the direct cause of the following exception:

Traceback (most recent call last):
  File "<stdin>", line 4, in <module>
RuntimeError: Failed to open database
```

异常链会在 except 或 finally子句内部引发异常时自动生成。 这可以通过使用 `from None` 这样的写法来禁用:

```python
try:
    open('database.sqlite')
except OSError:
    raise RuntimeError from None
```

